Workbook
Name phasegroups: '3 - Signal Group Info'!$B$6:$H$6
Name phasing: '[1]8 - Spec.Timers & Notes'!$S$35:$S$43
Name phasing: '8 - Spec.Timers & Notes'!$S$35:$S$43

Sheet 1 - Cover
A1: HAMILTON CITY COUNCIL
A2: Controller Information Sheet (C.I.S.)
A4: Intersection: | C4: Naylor / Galloway | G4: Site ID: | H4: 36
A5: Date: | B5: 43546 | D5: Version: | E5: 3d | G5: By: | H5: R Thomson
A6: SFT | C6: generated by | G6: Code: | H6: XLOSM

Sheet 2 - Install notes
A1: Intersection: | C1: ='1 - Cover'!C4 -> Naylor / Galloway | F1: Site ID: | G1: ='1 - Cover'!H4 -> 36
A2: Date: | B2: ='1 - Cover'!B5 -> 43546 | D2: Version: | E2: ='1 - Cover'!E5 -> 3d | F2: By: | G2: ='1 - Cover'!H5 -> R Thomson
C4: Warning
A6: This PROM requires hardware changes | I6: YES
A7: to the intersection before installation.
A8: Do Not install this PROM until the following
A9: hardware changes have been completed
A12: This PROM requires SCATS data changes | I12: YES
A13: to the intersection before installation.
A16: Controller Type | D16: ECLIPSE | F16: VC | H16: 5
M17: =IF(H20="","",IF(H20="NO","",IF(H22="LED",2,IF(H22="MIXED",1,""))))
A18: Lamp Dimming to be used | H18: YES
B20: Lamp Types installed (LED or MIXED) | H20: LED
B22: Dimming Level = | H22: =IF(H18="","",IF(H18="NO","",IF(H20="LED",2,IF(H20="MIXED",1,"")))) -> 2
A24: Filtering on MAIN RD | D24: N/A | F24: Filtering on SIDE RD | I24: N/A
A26: 1 | B26: Intersection Upgrade. Right turn from Galloway south approach into Naylor east control added (SG7) and D phase added. LTRA and RTRA pedestrian protection added.
A28: 2 | B28: Signal groups reconfigured.Opposing LT SG on north approach output changed from SG6 to SG12. Will need rewiring on site.
A30: 3 | B30: SCATS graphics and data needs updating
A32: 4 | B32: Det's 9,10, 11 and 12 not installed on site. Det Cat set to 1 to stop alarming.
A34: 5
A36: 6

Sheet 2a - Install notes SCATS CONFIG
A1: Intersection: | C1: ='1 - Cover'!C4:F4 -> Naylor / Galloway | F1: Site ID: | G1: ='1 - Cover'!H4 -> 36
A2: Date: | B2: ='1 - Cover'!B5 -> 43546 | D2: Version: | E2: ='1 - Cover'!E5 -> 3d | F2: By: | G2: ='1 - Cover'!H5 -> R Thomson
A4: SCATS DATA CONFIGURATION NOTES
A6: 1 | B6: V3 has full red arrow protection for ped P2. V3 has minimum off after ped clearance (subject to Z5), using C phase min. green time. Z5 facility required in C phase under masterlink. Late start required in C phase for V3.
A7: 2 | B7: V7 has full red arrow protection for ped P3. V7 has minimum off after ped clearance (subject to Z5), using A phase min. green time. Z5 facility required in A phase under masterlink. Late start required in A phase for V7.
A8: 3 | B8: V's 4 and 8 have FULL protection for P4 and P1 respectively. The phase may not terminate until the SG's have been OFF for the minimum phase time Adjust the SCATS ped data to prevent LC alarms. i.e. - W1T = P1 (CL1 + CL2) + BC phase (min. green + intergreen times).
A9: 4 | B9: V's 10 and 11 have timed red arrow protection for ped P2 and P4 walk and clearance. Red arrow time at SPT12 and SPT14 Phase cannot terminate until V's has displayed off for the phase minimum green time. Adjust the SCATS W2T data to prevent LC alarms. i.e. - W2T = P2 (CL1 + CL2) + C phase (min. green + intergreen times).
A10: 5 | B10: V9 has timed red arrow protection for ped P1 walk and clearance. Red arrow time at SPT11. Late start required in D phase for V9. BC phase cannot terminate until V9 has displayed off for C phase minimum green time. Adjust the SCATS W1T data to prevent LC alarms. W1T = P1 (CL1 + CL2) + BC phase (min. green + intergreen times).

Sheet 3 - Signal Group Info
A1: Intersection: | C1: ='1 - Cover'!C4 -> Naylor / Galloway | N1: Site ID: | P1: ='1 - Cover'!H4 -> 36
A2: Date: | C2: ='1 - Cover'!B5 -> 43546 | H2: Version: | J2: ='1 - Cover'!E5 -> 3d | N2: By: | O2: ='1 - Cover'!H5 -> R Thomson
A4: SIGNAL GROUP DEFINITIONS - Active phases | AA4: ='1 - Cover'!H6 -> XLOSM
AA5: ='2 - Install notes'!D24 -> N/A
A6: Phase Group | B6: A | C6: B | D6: =IF($AA$4="SDO","C(Z+)",IF($AA$4="SDOS","C(Z+)",IF($AA$4="SDOM","C(Z+)",IF($AA$4="SDOSM","C(Z+)",IF($AA$4="DDO","C(Z+)",IF($AA$4="DDOM","C(Z-+",IF($AA$4="DDOS","C(Z+)",IF($AA$4="DDOSM","C(Z+)",IF($AA$4="T","C)",IF($AA$4="TLM","C",IF($AA$4="TLS","C",IF($AA$4="TLSM","C","C")))))))))))) -> C | E6: D | F6: E | G6: =IF($AA$4="DDO","F(XSF5,XSF6)",IF($AA$4="DDOM","F(XSF5,XSF6)",IF($AA$4="DDOS","F(XSF5,XSF6)",IF($AA$4="DDOSM","F(XSF5,XSF6)","F")))) -> F | H6: G | I6: Table | J6: Phase Group | K6: =IF(ISBLANK(B6),"",B6) -> A | L6: =IF(ISBLANK(C6),"",C6) -> B | M6: =IF(ISBLANK(D6),"",D6) -> C | N6: =IF(ISBLANK(E6),"",E6) -> D | O6: =IF(ISBLANK(F6),"",F6) -> E | P6: =IF(ISBLANK(G6),"",G6) -> F | Q6: =IF(ISBLANK(H6),"",H6) -> G | R6: Table
A7: 1 | C7: B | D7: C | I7: 4 | J7: 9 | L7: B | M7: C | N7: D | R7: 76
A9: 2 | D9: C | I9: 1 | J9: 10 | M9: C | R9: 44
A11: 3 | C11: B | I11: 62 | J11: 11 | K11: A | N11: D | R11: 44
A13: 4 | D13: C | I13: 71 | J13: 12 | K13: A | L13: B | R13: 76
A15: 5 | B15: A | E15: D | I15: 4 | J15: P4(13) | K15: W | N15: W | R15: PD22M
A17: 6 | B17: A | I17: 1 | J17: P3(14) | K17: W | R17: PD2
A19: 7 | E19: D | I19: 62M | J19: P2(15) | M19: W | R19: PD1
A21: 8 | B21: A | E21: =IF($AA$4="DDO","D,D2",IF($AA$4="DDOM","D,D2",IF($AA$4="DDOS","D,D2",IF($AA$4="DDOSM","D,D2","")))) | G21: =IF($AA$4="DDO","F2",IF($AA$4="DDOM","F2",IF($AA$4="DDOS","F2",IF($AA$4="DDOSM","F2","")))) | I21: 71 | J21: P1(16) | L21: W | M21: W | R21: PD23M
D24: Signal Group Modifications
A26: SG | B26: Table | C26: Description
A27: =A19 -> 7 | B27: =IF(ISBLANK($A27),"",IF($A27<9,VLOOKUP($A27,$A$7:$I$22,9,FALSE),VLOOKUP($A27,$J$7:$R$22,9,FALSE))) -> 62M | C27: Modify to allow filtering when Z+ flag set in Flexi or Masterlink.
A28: =J21 -> P1(16) | B28: =IF(ISBLANK($A28),"",IF($A28<9,VLOOKUP($A28,$A$7:$I$22,9,FALSE),VLOOKUP($A28,$J$7:$R$22,9,FALSE))) -> PD23M | C28: Modify table to allow ped to run in Lag RT phase if the RT phase runs following the main through phase that has the opposing uncontrolled filter movement (i.e. in B if from C)
A29: =J15 -> P4(13) | B29: =IF(ISBLANK($A29),"",IF($A29<9,VLOOKUP($A29,$A$7:$I$22,9,FALSE),VLOOKUP($A29,$J$7:$R$22,9,FALSE))) -> PD22M | C29: Modify table to allow ped to run in Lag RT phase if the RT phase runs following the main through phase that has the opposing uncontrolled filter movement (i.e. in D if from A)
B30: =IF(ISBLANK($A30),"",IF($A30<9,VLOOKUP($A30,$A$7:$I$22,9,FALSE),VLOOKUP($A30,$J$7:$R$22,9,FALSE)))
B31: =IF(ISBLANK($A31),"",IF($A31<9,VLOOKUP($A31,$A$7:$I$22,9,FALSE),VLOOKUP($A31,$J$7:$R$22,9,FALSE)))
B32: =IF(ISBLANK($A32),"",IF($A32<9,VLOOKUP($A32,$A$7:$I$22,9,FALSE),VLOOKUP($A32,$J$7:$R$22,9,FALSE)))
B33: =IF(ISBLANK($A33),"",IF($A33<9,VLOOKUP($A33,$A$7:$I$22,9,FALSE),VLOOKUP($A33,$J$7:$R$22,9,FALSE)))
H37: PHASE INFORMATION
A39: Start Phase : | D39: A
A41: Phase Sequence: | D41: ABCD | J41: Alternative Sequence: | N41: CDAB
C47: Note: Throughout the Document
E49: Calculated results cell
E51: Fill in these cells where appropriate

Sheet 4 - Phase Control
A1: Intersection: | B1: ='1 - Cover'!C4 -> Naylor / Galloway | G1: Site ID: | H1: ='1 - Cover'!H4 -> 36
A2: Date: | B2: ='1 - Cover'!B5 -> 43546 | D2: Version: | F2: ='1 - Cover'!E5 -> 3d | G2: By: | H2: ='1 - Cover'!H5 -> R Thomson
A5: PROHIBITS AND MAXIMUM TRANSFERS
A7: From Phase | C7: Prohibit to | E7: Transfer Max to | G7: Steal Max from
A8: =IF(ISBLANK('3 - Signal Group Info'!B$6),"",'3 - Signal Group Info'!B$6) -> A
A9: =IF(ISBLANK('3 - Signal Group Info'!C$6),"",'3 - Signal Group Info'!C$6) -> B
A10: =IF(ISBLANK('3 - Signal Group Info'!D$6),"",'3 - Signal Group Info'!D$6) -> C
A11: =IF(ISBLANK('3 - Signal Group Info'!E$6),"",'3 - Signal Group Info'!E$6) -> D
A12: =IF(ISBLANK('3 - Signal Group Info'!F$6),"",'3 - Signal Group Info'!F$6) -> E
A13: =IF(ISBLANK('3 - Signal Group Info'!G$6),"",'3 - Signal Group Info'!G$6) -> F
A14: =IF(ISBLANK('3 - Signal Group Info'!H$6),"",'3 - Signal Group Info'!H$6) -> G
A17: MAXIMUM CONTROL AND REVERSION
A19: MAXIMUM CONTROL AND REVERSION
A20: Phase | C20: Software Arterial | E20: Reversion / Startup Reversion | G20: Use Max VIG on Reversion
A21: =A8 -> A | C21: YES | E21: YES
A22: =A9 -> B | E22: YES
A23: =A10 -> C | E23: YES
A24: =A11 -> D | E24: YES
A25: =A12 -> E
A26: =A13 -> F
A27: =A14 -> G
A29: Reversion: Occurs where maximum green is reached and passage loops only are used.
A30: Running phase will then recall and run again preventing possibility of trapped vehicles.
A31: Reversion is automatic for advance passage detectors (eg when Table 3 is specified)
A33: Max VIG on reversion should also be considered when advanced passage detectors
A34: are used
A36: Startup Reversion: Places an automatic demand for the nominated phase at start-up.

Sheet 5 - Detectors 
A1: Intersection: | E1: ='1 - Cover'!C4 -> Naylor / Galloway | I1: Site ID: | J1: ='1 - Cover'!H4 -> 36
A2: Date: | E2: ='1 - Cover'!B5 -> 43546 | G2: Version: | H2: ='1 - Cover'!E5 -> 3d | I2: By: | J2: ='1 - Cover'!H5 -> R Thomson
A4: DETECTORS
E6: Controller Inputs : | G6: 24
D8: VIG DETECTORS
D9: Det No. | E9: Approach SG | G9: Det No. | H9: Approach SG
B14: CALLING DETECTORS | J14: Red Light Running Data
B15: Phase | C15: Ped No. | E15: Locking | G15: Nonlocking | J15: Signal | K15: Virtual | L15: Actual
B16: ='4 - Phase Control'!A8 -> A | C16: P3(22),P4(21) | E16: 1,2,5,6 | J16: Group | K16: Detector | L16: Detectors
B17: ='4 - Phase Control'!A9 -> B | E17: 8 | G17: 8 | J17: 2 | K17: 17 | L17: 3
B18: ='4 - Phase Control'!A10 -> C | C18: P1(24),P2(23) | E18: 3,4,7,8 | J18: 5 | K18: 18 | L18: 5
B19: ='4 - Phase Control'!A11 -> D | E19: 6 | G19: 6
B20: ='4 - Phase Control'!A12 -> E
B21: ='4 - Phase Control'!A13 -> F
B22: ='4 - Phase Control'!A14 -> G | K22: =IF(J22="","",(K21+1))
B24: Counting Detectors
B26: DETECTOR ALARM CATEGORIES
B28: Det | C28: 1 | D28: 2 | E28: 3 | F28: 4 | G28: 5 | H28: 6 | I28: 7 | J28: 8 | K28: No of Detectors | L28: 12
B29: Cat | C29: 0 | D29: 0 | E29: =IF($L$28>2,0,1) -> 0 | F29: =IF($L$28>3,0,1) -> 0 | G29: =IF($L$28>4,0,1) -> 0 | H29: =IF($L$28>5,0,1) -> 0 | I29: =IF($L$28>6,0,1) -> 0 | J29: =IF($L$28>7,0,1) -> 0
B31: Det | C31: 9 | D31: 10 | E31: 11 | F31: 12 | G31: 13 | H31: 14 | I31: 15 | J31: 16
B32: Cat | C32: 1 | D32: 1 | E32: 1 | F32: 1 | G32: =IF($L$28>12,0,1) -> 1 | H32: =IF($L$28>13,0,1) -> 1 | I32: =IF($L$28>14,0,1) -> 1 | J32: =IF($L$28>15,0,1) -> 1
B34: Det | C34: 17 | D34: 18 | E34: 19 | F34: 20 | G34: 21 | H34: 22 | I34: 23 | J34: 24
B35: Cat | C35: =IF($L$28>16,0,1) -> 1 | D35: =IF($L$28>17,0,1) -> 1 | E35: =IF($L$28>18,0,1) -> 1 | F35: =IF($L$28>19,0,1) -> 1 | G35: =IF($L$28>20,0,1) -> 1 | H35: =IF($L$28>21,0,1) -> 1 | I35: =IF($L$28>22,0,1) -> 1 | J35: =IF($L$28>23,0,1) -> 1
A37: Push Button | C37: 1 | D37: 2 | E37: 3 | F37: 4 | G37: 5 | H37: 6 | I37: 7 | J37: 8 | K37: No of Peds | L37: 4
B38: Cat | C38: =IF($L$37<1,1,11) -> 11 | D38: =IF($L$37<2,1,11) -> 11 | E38: =IF($L$37<3,1,11) -> 11 | F38: =IF($L$37<4,1,11) -> 11 | G38: =IF($L$37<5,1,11) -> 1 | H38: =IF($L$37<6,1,11) -> 1 | I38: =IF($L$37<7,1,11) -> 1 | J38: =IF($L$37<8,1,11) -> 1
B40: Detector Types
B41: Detectors with alarms disabled
B42: Detectors with alarms ignored
A45: PRESENCE DETECTOR DELAYS
A47: Det | B47: Call Phase | C47: Delay Time | D47: Det | E47: Call Phase | F47: Delay Time | G47: Det | H47: Call Phase | I47: Delay Time | J47: Det | K47: Call Phase | L47: Delay Time
A48: 1 | D48: 9 | G48: 17 | J48: 25
A49: 2 | B49: A | C49: 2 | D49: 10 | G49: 18 | J49: 26
A50: 3 | D50: 11 | G50: 19 | J50: 27
A51: 4 | B51: C | C51: 2 | D51: 12 | G51: 20 | J51: 28
A52: 5 | D52: 13 | G52: 21 | J52: 29
A53: 6 | B53: D | C53: 2 | D53: 14 | G53: 22 | J53: 30
A54: 7 | B54: C | C54: 2 | D54: 15 | G54: 23 | J54: 31
A55: 8 | B55: B | C55: 2 | D55: 16 | G55: 24 | J55: 32

Sheet 5a - DAC's
A1: Site Description: | B1: ='1 - Cover'!C4 -> Naylor / Galloway | E1: Site No: | F1: ='1 - Cover'!H4 -> 36
A2: Last Updated: | B2: ='1 - Cover'!B5 -> 43546 | C2: Version: | D2: ='1 - Cover'!E5 -> 3d | E2: By: | F2: ='1 - Cover'!H5 -> R Thomson
A4: Description of Detector Alarm Categories
A6: NOTE: Category 0 = SCATS default alarming. Category 1 = Never Alarm
A8: CAT 2 - Busy Main Road Detector | C8: CAT 3 - Main Road Detector
A9: Normal Profile | B9: Alternate Profile (Sun) | C9: Normal Profile | E9: Alternate Profile (Sun and Sat)
A10: Zone A at 6:00 rate 30 mins | B10: Zone A at 9:00 rate 60 mins | C10: Zone A at 7:00 rate 30 mins | E10: Zone A at 9:00 rate 60 mins
A11: Zone B at 7:00 rate 10 mins | B11: Zone B at 18:00 but skipped | C11: Zone B at 7:30 rate 10 mins | E11: Zone B at 18:00 but skipped
A12: Zone C at 9:00 rate 30 mins | B12: Zone C at 18:00 but skipped | C12: Zone C at 9:00 rate 30 mins | E12: Zone C at 18:00 but skipped
A13: Zone D at 15:00 rate 10 mins | B13: Zone D at 18:00 but skipped | C13: Zone D at 15:00 rate 10 mins | E13: Zone D at 18:00 but skipped
A14: Zone E at 18:00 rate 60 mins | B14: Zone E at 18:00 but skipped | C14: Zone E at 18:00 rate 60 mins | E14: Zone E at 18:00 but skipped
A15: Zone F at 22:00 no checking | B15: Zone F at 18:00 no checking | C15: Zone F at 22:00 no checking | E15: Zone F at 18:00 no checking
A17: CAT 4 - Busy Minor Road Detector | C17: CAT 5 - Minor Road Detector
A18: Normal Profile | B18: Alternate Profile (Sun) | C18: Normal Profile | E18: Alternate Profile (Sun)
A19: Zone A at 7:00 rate 30 mins | B19: Zone A at 9:00 rate 60 mins | C19: Zone A at 7:00 rate 30 mins | E19: Zone A at 9:00 rate 60 mins
A20: Zone B at 7:30 rate 20 mins | B20: Zone B at 18:00 but skipped | C20: Zone B at 9:00 rate 60 mins | E20: Zone B at 18:00 but skipped
A21: Zone C at 9:00 rate 30 mins | B21: Zone C at 18:00 but skipped | C21: Zone C at 15:00 rate 30 mins | E21: Zone C at 18:00 but skipped
A22: Zone D at 15:00 rate 20 mins | B22: Zone D at 18:00 but skipped | C22: Zone D at 18:00 rate 60 mins | E22: Zone D at 18:00 but skipped
A23: Zone E at 18:00 rate 60 mins | B23: Zone E at 18:00 but skipped | C23: Zone E at 20:00 no checking | E23: Zone E at 18:00 but skipped
A24: Zone F at 20:00 no checking | B24: Zone F at 18:00 no checking | C24: Zone F at 20:00 no checking | E24: Zone F at 18:00 no checking
A26: CAT 6 - Non-Morning Detector | C26: CAT 7 - Non-Evening Detector
A27: Normal Profile | B27: Alternate Profile (Sun and Sat) | C27: Normal Profile | E27: Alternate Profile (Sun and Sat)
A28: Zone A at 9:00 rate 30 mins | B28: Zone A at 9:00 rate 60 mins | C28: Zone A at 7:00 rate 30 mins | E28: Zone A at 9:00 rate 60 mins
A29: Zone B at 15:00 rate 10 mins | B29: Zone B at 18:00 but skipped | C29: Zone B at 7:30 rate 20 mins | E29: Zone B at 18:00 but skipped
A30: Zone C at 18:00 rate 60 mins | B30: Zone C at 18:00 but skipped | C30: Zone C at 9:00 rate 30 mins | E30: Zone C at 18:00 but skipped
A31: Zone D at 22:00 but skipped | B31: Zone D at 18:00 but skipped | C31: Zone D at 18:00 rate 60 mins | E31: Zone D at 18:00 but skipped
A32: Zone E at 22:00 but skipped | B32: Zone E at 18:00 but skipped | C32: Zone E at 22:00 but skipped | E32: Zone E at 18:00 but skipped
A33: Zone F at 22:00 no checking | B33: Zone F at 18:00 no checking | C33: Zone F at 22:00 no checking | E33: Zone F at 18:00 no checking
A35: CAT 8 - Cycle Detector on Cycleway | C35: CAT 9 - Cycle Detector Predominantly for Schools
A36: Normal Profile | B36: Alternate Profile (Sun and Sat) | C36: Normal Profile | E36: Alternate Profile (Sun and Sat)
A37: Zone A at 7:00 rate 30 mins | B37: Zone A at 00:00 but skipped | C37: Zone A at 8:00 rate 20 mins | E37: Zone A at 00:00 but skipped
A38: Zone B at 7:30 rate 10 mins | B38: Zone B at 00:00 but skipped | C38: Zone B at 9:00 rate 360 mins | E38: Zone B at 00:00 but skipped
A39: Zone C at 9:00 rate 120 mins | B39: Zone C at 00:00 but skipped | C39: Zone C at 15:00 rate 10 mins | E39: Zone C at 00:00 but skipped
A40: Zone D at 15:00 rate 20 mins | B40: Zone D at 00:00 but skipped | C40: Zone D at 15:30 but skipped | E40: Zone D at 00:00 but skipped
A41: Zone E at 18:00 but skipped | B41: Zone E at 00:00 but skipped | C41: Zone E at 15:30 but skipped | E41: Zone E at 00:00 but skipped
A42: Zone F at 18:00 no checking | B42: Zone F at 00:00 but skipped | C42: Zone F at 15:30 no checking | E42: Zone F at 00:00 but skipped
A44: CAT 10 - Ped Detector in the CBD | C44: CAT 11 - Ped Detector in Lightly used Area
A45: Normal Profile | B45: Alternate Profile (Sun and Sat) | C45: Normal Profile | E45: Alternate Profile (Sun and Sat)
A46: Zone A at 9:00 rate 60 mins | B46: Zone A at 00:00 but skipped | C46: Zone A at 9:00 rate 120 mins | E46: Zone A at 00:00 but skipped
A47: Zone B at 18:00 but skipped | B47: Zone B at 00:00 but skipped | C47: Zone B at 18:00 but skipped | E47: Zone B at 00:00 but skipped
...

Sheet 6 - Time Settings
A1: Intersection: | C1: ='1 - Cover'!C4 -> Naylor / Galloway | J1: Ste ID: | K1: ='1 - Cover'!H4 -> 36
A2: Date: | B2: ='1 - Cover'!B5 -> 43546 | E2: Version: | G2: ='1 - Cover'!E5 -> 3d | J2: By: | K2: ='1 - Cover'!H5 -> R Thomson
B4: TIME SETTINGS
B6: PHASE | C6: LS | D6: LS SG | E6: MG | F6: IN | G6: MV | H6: MAX | I6: ECO | J6: ECO SG | K6: YEL | L6: RED | M6: SRED
B7: ='4 - Phase Control'!A8 -> A | C7: 5 | D7: 7 | E7: 5 | H7: 40 | K7: =IF('11 - All Red'!D19="","",'11 - All Red'!N19) -> 4 | L7: =IF(K7="","",'11 - All Red'!D19) -> 1.5 | M7: =IF(K7="","",'11 - All Red'!I19) -> 0
B8: ='4 - Phase Control'!A9 -> B | C8: 5 | D8: 1,3,9,12 | E8: 5 | H8: 20 | K8: =IF('11 - All Red'!D20="","",'11 - All Red'!N20) -> 4 | L8: =IF(K8="","",'11 - All Red'!D20) -> 2 | M8: =IF(K8="","",'11 - All Red'!I20) -> 0
B9: ='4 - Phase Control'!A10 -> C | C9: 5 | D9: 3 | E9: 5 | H9: 40 | K9: =IF('11 - All Red'!D21="","",'11 - All Red'!N21) -> 4 | L9: =IF(K9="","",'11 - All Red'!D21) -> 2 | M9: =IF(K9="","",'11 - All Red'!I21) -> 0
B10: ='4 - Phase Control'!A11 -> D | C10: 5 | D10: 5,7,9, 11 | E10: 5 | H10: 20 | K10: =IF('11 - All Red'!D22="","",'11 - All Red'!N22) -> 4 | L10: =IF(K10="","",'11 - All Red'!D22) -> 1.5 | M10: =IF(K10="","",'11 - All Red'!I22) -> 0
B11: ='4 - Phase Control'!A12 -> E | H11: =IF($K11="","",25) | K11: =IF('11 - All Red'!D23="","",'11 - All Red'!N23) | L11: =IF(K11="","",'11 - All Red'!D23) | M11: =IF(K11="","",'11 - All Red'!I23)
B12: ='4 - Phase Control'!A13 -> F | E12: =IF($K12="","",5) | H12: =IF($K12="","",25) | K12: =IF('11 - All Red'!D24="","",'11 - All Red'!N24) | L12: =IF(K12="","",'11 - All Red'!D24) | M12: =IF(K12="","",'11 - All Red'!I24)
B13: ='4 - Phase Control'!A14 -> G | E13: =IF($K13="","",5) | H13: =IF($K13="","",25) | K13: =IF('11 - All Red'!D25="","",'11 - All Red'!N25) | L13: =IF(K13="","",'11 - All Red'!D25) | M13: =IF(K13="","",'11 - All Red'!I25)
A15: Phase | B15: Dets | C15: Table | D15: SG | E15: Appr No. | F15: Gap | G15: Hwy | H15: Waste | I15: Dets | J15: Table | K15: SG | L15: Appr No. | M15: App Timer Setting (1-4)
A17: =B7 -> A | B17: 5 | C17: 6M | D17: 5 | E17: 1 | F17: 3 | G17: 1.2 | H17: 15 | I17: 9 | J17: 1 | K17: =D18 -> 6 | L17: 5 | M17: 4
B18: 1,2 | C18: 1M | D18: 6 | E18: 2 | F18: 3 | G18: 1.2 | H18: 15 | L18: 6
B19: 6 | C19: 16M | D19: 5 | E19: 3 | F19: 3 | G19: 0.8 | H19: 15 | L19: 7
B20: 11 | C20: =C17 -> 6M | D20: =D17 -> 5 | E20: 4 | F20: 3.5 | G20: 2.5 | H20: 15 | L20: 8
A21: =B8 -> B | B21: =B25 -> 7 | C21: =C25 -> 6M | D21: =D25 -> 1 | E21: 1 | F21: =F25 -> 3 | G21: =G25 -> 1.2 | H21: =H25 -> 15 | L21: 5
B22: =B27 -> 8 | C22: =C27 -> 16M | D22: 3 | E22: 2 | F22: =F27 -> 3 | G22: =G27 -> 0.8 | H22: =H27 -> 15 | L22: 6
B23: 12 | C23: =C25 -> 6M | D23: =D25 -> 1 | E23: 3 | F23: 3.5 | G23: 2.5 | H23: 15 | L23: 7
E24: 4 | L24: 8
A25: =B9 -> C | B25: 7 | C25: 6M | D25: 1 | E25: 1 | F25: 3 | G25: 1.2 | H25: 15 | I25: 10 | J25: 1 | K25: 2 | L25: 5 | M25: 4
B26: 3,4 | C26: 1M | D26: 2 | E26: 2 | F26: 3 | G26: 1.2 | H26: 15 | L26: 6
B27: 8 | C27: 16M | D27: 1 | E27: 3 | F27: 3 | G27: 0.8 | H27: 15 | L27: 7
B28: =B23 -> 12 | C28: =C23 -> 6M | D28: =D23 -> 1 | E28: 4 | F28: =F23 -> 3.5 | G28: =G23 -> 2.5 | H28: =H23 -> 15 | L28: 8
A29: =B10 -> D | B29: =B17 -> 5 | C29: =C17 -> 6M | D29: =D17 -> 5 | E29: 1 | F29: =F17 -> 3 | G29: =G17 -> 1.2 | H29: =H17 -> 15 | L29: 5
B30: =B19 -> 6 | C30: =C19 -> 16M | D30: 7 | E30: 2 | F30: =F19 -> 3 | G30: =G19 -> 0.8 | H30: =H19 -> 15 | L30: 6
B31: =B20 -> 11 | C31: =C20 -> 6M | D31: =D20 -> 5 | E31: 3 | F31: =F20 -> 3.5 | G31: =G20 -> 2.5 | H31: =H20 -> 15 | L31: 7
E32: 4 | L32: 8
A33: =B11 -> E | E33: 1 | L33: 5
E34: 2 | L34: 6
E35: 3 | L35: 7
E36: 4 | L36: 8
A37: =B12 -> F | E37: 1 | L37: 5
E38: 2 | L38: 6
E39: 3 | L39: 7
E40: 4 | L40: 8
A41: =B13 -> G | E41: 1 | L41: 5
E42: 2 | L42: 6
E43: 3 | L43: 7
E44: 4 | L44: 8
...

Sheet 7 - Peds
A1: Intersection: | C1: ='1 - Cover'!C4 -> Naylor / Galloway | I1: Site ID: | J1: ='1 - Cover'!H4 -> 36
A2: Date: | B2: ='1 - Cover'!B5 -> 43546 | E2: Version: | G2: ='1 - Cover'!E5 -> 3d | I2: By: | J2: ='1 - Cover'!H5 -> R Thomson
A6: PEDESTRIAN TIMES
B8: Ped No | C8: Table No | D8: Ped Operates in Phases | E8: Callaway Phase | F8: SG No | G8: Delay Time | H8: Cross | I8: Clear 1 | J8: Clear 2 | K8: Ped Protection Y/N
B10: =IF(COUNTIF('3 - Signal Group Info'!$A$7:$A$22,"P1*")+COUNTIF('3 - Signal Group Info'!$J$7:$J$22,"P1*")>0,"P1","") -> P1 | C10: =IF(B10="","",IF(ISNUMBER(MATCH(B10&"*",'3 - Signal Group Info'!$A$7:$A$22,0)),VLOOKUP(B10&"*",'3 - Signal Group Info'!$A$7:$I$22,9,FALSE),IF(ISNUMBER(MATCH(B10&"*",'3 - Signal Group Info'!$J$7:$J$22,0)),VLOOKUP(B10&"*",'3 - Signal Group Info'!$J$7:$R$22,9,FALSE),""))) -> PD23M | D10: =VLOOKUP(B10,Lists!I2:K17,3,FALSE) -> B/C | E10: A | F10: =IF($B10="","",VLOOKUP($B10,Lists!$I$2:$L$17,4,FALSE)) -> 16 | H10: =IF($B10="","",'11 - All Red'!J8) -> 6 | I10: =IF($B10="","",'11 - All Red'!K8) -> 9.3333333 | J10: =IF($B10="","",'11 - All Red'!L8) -> 4 | K10: =IF(OR(B30="Y",C30="Y"),"Y",IF(OR(B30="N",C30="N"),"N"," ")) -> Y
B11: =IF(COUNTIF('3 - Signal Group Info'!$A$7:$A$22,"P2*")+COUNTIF('3 - Signal Group Info'!$J$7:$J$22,"P2*")>0,"P2","") -> P2 | C11: =IF(B11="","",IF(ISNUMBER(MATCH(B11&"*",'3 - Signal Group Info'!$A$7:$A$22,0)),VLOOKUP(B11&"*",'3 - Signal Group Info'!$A$7:$I$22,9,FALSE),IF(ISNUMBER(MATCH(B11&"*",'3 - Signal Group Info'!$J$7:$J$22,0)),VLOOKUP(B11&"*",'3 - Signal Group Info'!$J$7:$R$22,9,FALSE),""))) -> PD1 | D11: =VLOOKUP(B11,Lists!I3:K18,3,FALSE) -> C | E11: A | F11: =IF($B11="","",VLOOKUP($B11,Lists!$I$2:$L$17,4,FALSE)) -> 15 | H11: =IF($B11="","",'11 - All Red'!J9) -> 6 | I11: =IF($B11="","",'11 - All Red'!K9) -> 12.666667 | J11: =IF($B11="","",'11 - All Red'!L9) -> 4 | K11: =IF(OR(B32="Y",C32="Y"),"Y",IF(OR(B32="N",C32="N"),"N"," ")) -> Y
B12: =IF(COUNTIF('3 - Signal Group Info'!$A$7:$A$22,"P3*")+COUNTIF('3 - Signal Group Info'!$J$7:$J$22,"P3*")>0,"P3","") -> P3 | C12: =IF(B12="","",IF(ISNUMBER(MATCH(B12&"*",'3 - Signal Group Info'!$A$7:$A$22,0)),VLOOKUP(B12&"*",'3 - Signal Group Info'!$A$7:$I$22,9,FALSE),IF(ISNUMBER(MATCH(B12&"*",'3 - Signal Group Info'!$J$7:$J$22,0)),VLOOKUP(B12&"*",'3 - Signal Group Info'!$J$7:$R$22,9,FALSE),""))) -> PD2 | D12: =VLOOKUP(B12,Lists!I4:K19,3,FALSE) -> A | E12: C | F12: =IF($B12="","",VLOOKUP($B12,Lists!$I$2:$L$17,4,FALSE)) -> 14 | H12: =IF($B12="","",'11 - All Red'!J10) -> 6 | I12: =IF($B12="","",'11 - All Red'!K10) -> 9 | J12: =IF($B12="","",'11 - All Red'!L10) -> 3.5 | K12: =IF(OR(B34="Y",C34="Y"),"Y",IF(OR(B34="N",C34="N"),"N"," ")) -> Y
B13: =IF(COUNTIF('3 - Signal Group Info'!$A$7:$A$22,"P4*")+COUNTIF('3 - Signal Group Info'!$J$7:$J$22,"P4*")>0,"P4","") -> P4 | C13: =IF(B13="","",IF(ISNUMBER(MATCH(B13&"*",'3 - Signal Group Info'!$A$7:$A$22,0)),VLOOKUP(B13&"*",'3 - Signal Group Info'!$A$7:$I$22,9,FALSE),IF(ISNUMBER(MATCH(B13&"*",'3 - Signal Group Info'!$J$7:$J$22,0)),VLOOKUP(B13&"*",'3 - Signal Group Info'!$J$7:$R$22,9,FALSE),""))) -> PD22M | D13: =VLOOKUP(B13,Lists!I5:K20,3,FALSE) -> A/D | E13: C | F13: =IF($B13="","",VLOOKUP($B13,Lists!$I$2:$L$17,4,FALSE)) -> 13 | H13: =IF($B13="","",'11 - All Red'!J11) -> 6 | I13: =IF($B13="","",'11 - All Red'!K11) -> 10.666667 | J13: =IF($B13="","",'11 - All Red'!L11) -> 3.5 | K13: =IF(OR(B36="Y",C36="Y"),"Y",IF(OR(B36="N",C36="N"),"N"," ")) -> Y
B14: =IF(COUNTIF('3 - Signal Group Info'!$A$7:$A$22,"P5*")+COUNTIF('3 - Signal Group Info'!$J$7:$J$22,"P5*")>0,"P5","") | C14: =IF(B14="","",IF(ISNUMBER(MATCH(B14&"*",'3 - Signal Group Info'!$A$7:$A$22,0)),VLOOKUP(B14&"*",'3 - Signal Group Info'!$A$7:$I$22,9,FALSE),IF(ISNUMBER(MATCH(B14&"*",'3 - Signal Group Info'!$J$7:$J$22,0)),VLOOKUP(B14&"*",'3 - Signal Group Info'!$J$7:$R$22,9,FALSE),""))) | D14: =VLOOKUP(B14,Lists!I6:K21,3,FALSE) | F14: =IF($B14="","",VLOOKUP($B14,Lists!$I$2:$L$17,4,FALSE)) | H14: =IF($B14="","",'11 - All Red'!J12) | I14: =IF($B14="","",'11 - All Red'!K12) | J14: =IF($B14="","",'11 - All Red'!L12) | K14: =IF(OR(B38="Y",C38="Y"),"Y",IF(OR(B38="N",C38="N"),"N"," "))
B15: =IF(COUNTIF('3 - Signal Group Info'!$A$7:$A$22,"P6*")+COUNTIF('3 - Signal Group Info'!$J$7:$J$22,"P6*")>0,"P6","") | C15: =IF(B15="","",IF(ISNUMBER(MATCH(B15&"*",'3 - Signal Group Info'!$A$7:$A$22,0)),VLOOKUP(B15&"*",'3 - Signal Group Info'!$A$7:$I$22,9,FALSE),IF(ISNUMBER(MATCH(B15&"*",'3 - Signal Group Info'!$J$7:$J$22,0)),VLOOKUP(B15&"*",'3 - Signal Group Info'!$J$7:$R$22,9,FALSE),""))) | D15: =VLOOKUP(B15,Lists!I7:K22,3,FALSE) | F15: =IF($B15="","",VLOOKUP($B15,Lists!$I$2:$L$17,4,FALSE)) | H15: =IF($B15="","",'11 - All Red'!J13) | I15: =IF($B15="","",'11 - All Red'!K13) | J15: =IF($B15="","",'11 - All Red'!L13) | K15: =IF(OR(B40="Y",C40="Y"),"Y",IF(OR(B40="N",C40="N"),"N"," "))
B16: =IF(COUNTIF('3 - Signal Group Info'!$A$7:$A$22,"P7*")+COUNTIF('3 - Signal Group Info'!$J$7:$J$22,"P7*")>0,"P7","") | C16: =IF(B16="","",IF(ISNUMBER(MATCH(B16&"*",'3 - Signal Group Info'!$A$7:$A$22,0)),VLOOKUP(B16&"*",'3 - Signal Group Info'!$A$7:$I$22,9,FALSE),IF(ISNUMBER(MATCH(B16&"*",'3 - Signal Group Info'!$J$7:$J$22,0)),VLOOKUP(B16&"*",'3 - Signal Group Info'!$J$7:$R$22,9,FALSE),""))) | D16: =VLOOKUP(B16,Lists!I8:K23,3,FALSE) | F16: =IF($B16="","",VLOOKUP($B16,Lists!$I$2:$L$17,4,FALSE)) | H16: =IF($B16="","",'11 - All Red'!J14) | I16: =IF($B16="","",'11 - All Red'!K14) | J16: =IF($B16="","",'11 - All Red'!L14) | K16: =IF(OR(B42="Y",C42="Y"),"Y",IF(OR(B42="N",C42="N"),"N"," "))
B17: =IF(COUNTIF('3 - Signal Group Info'!$A$7:$A$22,"P8*")+COUNTIF('3 - Signal Group Info'!$J$7:$J$22,"P8*")>0,"P8","") | C17: =IF(B17="","",IF(ISNUMBER(MATCH(B17&"*",'3 - Signal Group Info'!$A$7:$A$22,0)),VLOOKUP(B17&"*",'3 - Signal Group Info'!$A$7:$I$22,9,FALSE),IF(ISNUMBER(MATCH(B17&"*",'3 - Signal Group Info'!$J$7:$J$22,0)),VLOOKUP(B17&"*",'3 - Signal Group Info'!$J$7:$R$22,9,FALSE),""))) | D17: =VLOOKUP(B17,Lists!I9:K24,3,FALSE) | F17: =IF($B17="","",VLOOKUP($B17,Lists!$I$2:$L$17,4,FALSE)) | H17: =IF($B17="","",'11 - All Red'!J15) | I17: =IF($B17="","",'11 - All Red'!K15) | J17: =IF($B17="","",'11 - All Red'!L15) | K17: =IF(OR(B45="Y",C45="Y"),"Y",IF(OR(B45="N",C45="N"),"N"," ")) | O17: =IF(LEFT('3 - Signal Group Info'!$J$15,2)=("P"&B17),'3 - Signal Group Info'!$R$15,IF(LEFT('3 - Signal Group Info'!$J$17,2)=("P"&B17),'3 - Signal Group Info'!$R$17,IF(LEFT('3 - Signal Group Info'!$J$19,2)=("P"&B17),'3 - Signal Group Info'!$R$19,IF(LEFT('3 - Signal Group Info'!$J$21,2)=("P"&B17),'3 - Signal Group Info'!$R$21,""))))
B21: Wait Extinguish : | E21: Y
A26: PEDESTRIAN PROTECTION TYPE
B28: Type of Protection | D28: Conflicting Signal Group | F28: Timer | H28: Comments
B29: Partial | C29: Full
A30: =IF(B10="","",B10) -> P1 | B30: Y | D30: 9 | F30: =IF(B30="Y","SPT1"&RIGHT(A30,1),"") -> SPT11
C31: Y | D31: 4 | F31: =IF(B31="Y","SPT1"&RIGHT(A30,1),"")
A32: P2 | B32: Y | D32: 10 | F32: =IF(B32="Y","SPT1"&RIGHT(A32,1),"") -> SPT12
C33: Y | D33: 3
A34: P3 | B34: Y | D34: 12 | F34: =IF(B34="Y","SPT1"&RIGHT(A34,1),"") -> SPT13
C35: Y | D35: 7
A36: P4 | B36: Y | D36: 11 | F36: =IF(B36="Y","SPT1"&RIGHT(A36,1),"") -> SPT14
C37: Y | D37: 8
A38: P5 | F38: =IF(B38="Y","SPT1"&RIGHT(A38,1),"")
A40: P6 | F40: =IF(B40="Y","SPT1"&RIGHT(A40,1),"")
A42: P7 | F42: =IF(B42="Y","SPT1"&RIGHT(A42,1),"")
A44: P8
F45: =IF(B45="Y","SPT1"&RIGHT(A44,1),"")
D47: Delete these notes on the working copy
A48: Where: | B48: Partial Ped Protection requires a timer for the Red Arrow protection
B50: Full Ped Protection does not require a timer as the SG Table uses the Walk-Clearance + Z5 flag
B51: to hold the Red Arrow and introduces the Green at end of the Red Arrow SG at the end of Ped
B52: subject to the Z5 flag.
B54: If a Ped does not require ANY protection, then answer N to both and put note in comment field
B55: eg. "None required."

Sheet 8 - Spec.Timers & Notes
A1: Intersection: | C1: ='1 - Cover'!C4 -> Naylor / Galloway | I1: Site ID: | J1: ='1 - Cover'!H4 -> 36
A2: Date: | B2: ='1 - Cover'!B5 -> 43546 | E2: Version: | G2: ='1 - Cover'!E5 -> 3d | I2: By: | J2: ='1 - Cover'!H5 -> R Thomson
A4: SPECIAL PURPOSE TIMERS | O4: ='1 - Cover'!H6 -> XLOSM
O5: ='2 - Install notes'!D24 -> N/A
A6: Timer | B6: Function | D6: Value | E6: Timer | F6: Function | H6: Value | I6: Timer | J6: Function | L6: Value
A7: 1 | E7: 9 | I7: 17
A8: 2 | E8: 10 | F8: =IF($O$4="DDO","D or F Isolated demand",IF($O$4="DDOM","D or F Isolated demand",IF($O$4="DDOS","D or F Isolated demand",IF($O$4="DDSOM","D or F Isolated demand","")))) | H8: =IF($O$4="DDO","200",IF($O$4="DDOM","200",IF($O$4="DDOS","200",IF($O$4="DDSOM","200","")))) | I8: 18
A9: 3 | E9: 11 | F9: P1 protection SG9 | H9: 6 | I9: 19
A10: 4 | E10: 12 | F10: P2 protection SG10 | H10: 6 | I10: 20 | J10: All-Red on start up | L10: 10
A11: 5 | E11: 13 | F11: P3 protection SG12 | H11: 6 | I11: 25
A12: 6 | E12: 14 | F12: P4 protection SG11 | H12: 6 | I12: 26
A13: 7 | E13: 15 | I13: 27
A14: 8 | E14: 16 | I14: 28
D16: Audio times set for audio tactile
D17: TSH=06 TSM=55 (start 06:55hrs)
D18: TFH=20 TFM=45 (finish 20:45hrs)
B21: Lamp Dimming Schedule | I21: Lamp Dimming Voltage Settings
B22: Dimming Times | D22: Summer Dawn | F22: =IF('1 - Cover'!$A$1="DUNEDIN CITY COUNCIL","05:42 hrs",IF('1 - Cover'!$A$1="HAMILTON CITY COUNCIL","05:55hrs",IF('1 - Cover'!$A$1="NAPIER CITY COUNCIL","05:30hrs",IF('1 - Cover'!$A$1="WHANGAREI DISTRICT COUNCIL","05:45hrs",IF('1 - Cover'!$A$1="NEW PLYMOUTH DISTRICT COUNCIL","05:45 hrs",IF('1 - Cover'!$A$1="WHANGANUI DISTRICT COUNCIL","05:30 hrs",0)))))) -> 05:55hrs | I22: Normal | K22: 230v
D23: Winter Sunrise | F23: =IF('1 - Cover'!$A$1="DUNEDIN CITY COUNCIL","08:20 hrs",IF('1 - Cover'!$A$1="HAMILTON CITY COUNCIL","07:30hrs",IF('1 - Cover'!$A$1="NAPIER CITY COUNCIL","07:05hrs",IF('1 - Cover'!$A$1="WHANGAREI DISTRICT COUNCIL","07:10hrs",IF('1 - Cover'!$A$1="NEW PLYMOUTH DISTRICT COUNCIL","07:15 hrs",IF('1 - Cover'!$A$1="WHANGANUI DISTRICT COUNCIL","07:15 hrs",0)))))) -> 07:30hrs | I23: Level 1 | K23: =IF(K25=1,"216v",IF(K25=2,"207v","207v")) -> 207v
D24: Winter Sunset | F24: =IF('1 - Cover'!$A$1="DUNEDIN CITY COUNCIL","16:59 hrs",IF('1 - Cover'!$A$1="HAMILTON CITY COUNCIL","17:00hrs",IF('1 - Cover'!$A$1="NAPIER CITY COUNCIL","17:10hrs",IF('1 - Cover'!$A$1="WHANGAREI DISTRICT COUNCIL","17:30hrs",IF('1 - Cover'!$A$1="NEW PLYMOUTH DISTRICT COUNCIL","17:15 hrs",IF('1 - Cover'!$A$1="WHANGANUI DISTRICT COUNCIL","17:10 hrs",0)))))) -> 17:00hrs | I24: Level 2 | K24: 184v
D25: Summer Dusk | F25: =IF('1 - Cover'!$A$1="DUNEDIN CITY COUNCIL","21:31 hrs",IF('1 - Cover'!$A$1="HAMILTON CITY COUNCIL","20:50hrs",IF('1 - Cover'!$A$1="NAPIER CITY COUNCIL","21:00hrs",IF('1 - Cover'!$A$1="WHANGAREI DISTRICT COUNCIL","20:55hrs",IF('1 - Cover'!$A$1="NEW PLYMOUTH DISTRICT COUNCIL","21:05 hrs",IF('1 - Cover'!$A$1="WHANGANUI DISTRICT COUNCIL","21:05 hrs",0)))))) -> 20:50hrs | I25: Dimming Level | K25: ='2 - Install notes'!H22 -> 2
I27: Set DIM command in SFT | K27: =IF(K25=1,"ALWAYS,DIM1",IF(K25=2,"ALWAYS, DIM2","")) -> ALWAYS, DIM2
B28: MODES
B29: MODES | D29: 03D1
B30: CMODE | D30: 0ABF
B31: XMODE | D31: 0000 | F31: For Ramp Metering XMODE = 0001
A33: NOTES
A35: 1 | B35: 4 phase Cross Road with Lead RT's (Filter/Non Filter both approaches) | R35: =IF(K25=1,"216v",IF(K25=2,"207v","207v")) -> 207v
A36: 2 | S36: Single Diamond Overlap Non Filter with Combined Side Road phase
S37: Single Diamond Overlap Filter/Non Filter with Combined Side Road phase
A38: 3 | S38: Single Diamond Overlap Non Filter with Split Side Road phase
S39: Single Diamond Overlap Filter/Non Filter with Split Side Road phase
A40: 4 | S40: Double Diamond Overlap Non Filter with Combined Side Road phase
S41: Double Diamond Overlap Filter/Non Filter with Combined Side Road phase
S42: Double Diamond Overlap Non Filter with Split Side Road phase
S43: Double Diamond Overlap Filter/Non Filter with Split Side Road phase
A44: SPECIAL LOGIC NOTES
A46: 1
A48: 2
A50: 3
...

Sheet 9 - Flexi & Special Flags
A1: Intersection: | C1: ='1 - Cover'!C4 -> Naylor / Galloway | H1: Site ID: | I1: ='1 - Cover'!H4 -> 36 | L1: Intersection: | N1: ='1 - Cover'!C4 -> Naylor / Galloway | AA1: Site ID: | AD1: ='1 - Cover'!H4 -> 36
A2: Date: | B2: ='1 - Cover'!B5 -> 43546 | E2: Version: | F2: ='1 - Cover'!E5 -> 3d | H2: By: | I2: ='1 - Cover'!H5 -> R Thomson | L2: Date: | M2: ='1 - Cover'!B5 -> 43546 | V2: Version: | W2: ='1 - Cover'!E5 -> 3d | AB2: By: | AC2: ='1 - Cover'!H5 -> R Thomson
C4: FLEXI LINK DATA - Sequence 1 | H4: ='3 - Signal Group Info'!D41 -> ABCD | L4: Flexilink Plan Data | R4: Pulse Step | U4: 1 | AI4: ='1 - Cover'!H6 -> XLOSM
A6: Phase | E6: Look Ahead To | H6: Release | L6: Plan | M6: CL | N6: A | O6: B | P6: C | Q6: D | R6: E | S6: F | T6: G | U6: R- | V6: R+ | W6: Y- | X6: Y+ | Y6: Z- | Z6: Z+ | AA6: Q- | AB6: Q+ | AC6: XSF
H7: (R-, R+, Q-, Q+) | L7: 0
A8: ='4 - Phase Control'!A8:B8 -> A | E8: PIVOT | H8: R- | L8: 1
A9: ='4 - Phase Control'!A9:B9 -> B | E9: CDA | H9: R+ | L9: 2
A10: ='4 - Phase Control'!A10:B10 -> C | E10: DA | H10: Q- | L10: 3
A11: ='4 - Phase Control'!A11:B11 -> D | E11: A | H11: Q+ | L11: 4
A12: ='4 - Phase Control'!A12:B12 -> E | L12: 5
A13: ='4 - Phase Control'!A13:B13 -> F | L13: 6
A14: ='4 - Phase Control'!A14:B14 -> G | L14: 7
A15: Note: No look ahead on Pivot Phase | L15: 8
L16: 9
L17: 10
C18: FLEXI LINK DATA - Sequence 2 | H18: ='3 - Signal Group Info'!N41 -> CDAB
A20: Phase | E20: Look Ahead To | H20: Release | L20: Flexilink Schedule Data
H21: (R-, R+, Q-, Q+)
A22: =A8 -> A | E22: BC | H22: =H8 -> R- | M22: 1 | N22: 2 | O22: 3 | P22: 4 | Q22: 5 | R22: 6 | S22: 7 | T22: 8 | U22: 9 | V22: 10 | W22: 11 | X22: 12 | Y22: 13 | Z22: 14 | AA22: 15 | AB22: 16 | AC22: 17 | AD22: 18 | AE22: 19 | AF22: 20
A23: =A9 -> B | E23: C | H23: =H9 -> R+ | L23: Day
A24: =A10 -> C | E24: PIVOT | H24: Q- | L24: Hour
A25: =A11 -> D | E25: ABC | H25: Q+ | L25: Min
A26: =A12 -> E | L26: Plan
A27: =A13 -> F
A28: =A14 -> G
A29: Note: No look ahead on Pivot Phase
A32: MASTERLINK & FLEXILINK SPECIAL FLAGS
A34: Flag | C34: Function
A35: Y- | B35: Flexi | C35: C' (Continuous) entry or an offset value will enable Flexilink
A36: Y- | B36: Master | C36: Auto recall for pedestrian demands
A37: Y+ | B37: Flexi | C37: Run alternative sequence
A38: Z- | B38: Flexi | C38: Allow SG 3 to Filter in C
A39: Z- | B39: Master | C39: =C38 -> Allow SG 3 to Filter in C
A40: Z+ | B40: Flexi | C40: Allow SG 7 to Filter in A
A41: Z+ | B41: Master | C41: =C40 -> Allow SG 7 to Filter in A
A43: XSF1 | B43: Master
A44: XSF2 | B44: Flexi,Master
A45: XSF3 | B45: Flexi,Master
A46: XSF4 | B46: Flexi,Master
A47: XSF5 | B47: Master
...

Sheet 10 - Conflict Matrix
A1: Intersection: | F1: ='1 - Cover'!C4 -> Naylor / Galloway | T1: Site ID: | U1: ='1 - Cover'!H4 -> 36 | AE1: ='1 - Cover'!H6 -> XLOSM
A2: Date: | C2: ='1 - Cover'!B5 -> 43546 | H2: Version: | L2: ='1 - Cover'!E5 -> 3d | T2: By: | U2: ='1 - Cover'!H5 -> R Thomson | AE2: ='2 - Install notes'!D24 -> N/A
AE3: ='2 - Install notes'!I24 -> N/A
A4: CONFLICT MATRIX | AH4: ='1 - Cover'!H6 -> XLOSM
C6: MA | D6: MA | E6: MI | F6: MI | G6: MA | H6: MA | I6: MI | J6: MI | K6: MI | L6: MI | M6: MI | N6: MI | O6: P4 | P6: P3 | Q6: P2 | R6: P1
B7: SG | C7: 1 | D7: 2 | E7: 3 | F7: 4 | G7: 5 | H7: 6 | I7: 7 | J7: 8 | K7: 9 | L7: 10 | M7: 11 | N7: 12 | O7: 13 | P7: 14 | Q7: 15 | R7: 16 | S7: 17 | T7: 18 | U7: 19 | V7: 20 | W7: 21 | X7: 22 | Y7: 23 | Z7: 24
A8: =IF(C$6="","",C$6) -> MA | B8: =INDEX($1:$1048576,7,ROW()-5) -> 1 | G8: X | H8: X | I8: X | J8: =IF($AH$4="DDO","X",IF($AH$4="DDOM","X",IF($AH$4="DDOS","X",IF($AH$4="DDOSM","X","")))) | O8: X | P8: X | AC8: Checker Off
A9: =IF(D$6="","",D$6) -> MA | B9: =INDEX($1:$1048576,7,ROW()-5) -> 2 | E9: X | G9: X | H9: X | I9: X | J9: =IF($AH$4="DDO","X",IF($AH$4="DDOM","X",IF($AH$4="DDOS","X",IF($AH$4="DDOSM","X","")))) | N9: X | O9: X | P9: X
A10: =IF(E$6="","",E$6) -> MI | B10: =INDEX($1:$1048576,7,ROW()-5) -> 3 | D10: X | G10: X | H10: X | I10: X | P10: X | Q10: X
A11: =IF(F$6="","",F$6) -> MI | B11: =INDEX($1:$1048576,7,ROW()-5) -> 4 | H11: =IF($AH$4="SDO","X",IF($AH$4="SDOS","X",IF($AH$4="SDOM","X",IF($AH$4="SDOSM","X",IF($AH$4="DDO","X",IF($AH$4="DDOM","X",IF($AH$4="DDOS","X",IF($AH$4="DDOSM","X","")))))))) | I11: =IF($AH$4="DDO","X",IF($AH$4="DDOM","X",IF($AH$4="DDOS","X",IF($AH$4="DDOSM","X","")))) | J11: =IF($AH$4="T","X",IF($AH$4="TLSM","X",IF($AH$4="TLM","X",IF($AH$4="DDOSM","X",""))))
A12: =IF(G$6="","",G$6) -> MA | B12: =INDEX($1:$1048576,7,ROW()-5) -> 5 | C12: X | D12: X | E12: X | H12: =IF($AH$4="SDO","X",IF($AH$4="SDOS","X",IF($AH$4="SDOM","X",IF($AH$4="SDOSM","X","")))) | J12: =IF($AH$4="DDO","X",IF($AH$4="DDOM","X",IF($AH$4="DDOS","X",IF($AH$4="DDOSM","X","")))) | Q12: X | R12: X
A13: =IF(H$6="","",H$6) -> MA | B13: =INDEX($1:$1048576,7,ROW()-5) -> 6 | C13: X | D13: X | E13: X | I13: X | J13: =IF($AH$4="T","X",IF($AH$4="TLSM","X",IF($AH$4="TLM","X",IF($AH$4="DDOSM","X","")))) | K13: X | Q13: X | R13: X
A14: =IF(I$6="","",I$6) -> MI | B14: =INDEX($1:$1048576,7,ROW()-5) -> 7 | C14: X | D14: X | E14: X | H14: X | N14: X | P14: X | R14: X
A15: =IF(J$6="","",J$6) -> MI | B15: =INDEX($1:$1048576,7,ROW()-5) -> 8
A16: =IF(K$6="","",K$6) -> MI | B16: =INDEX($1:$1048576,7,ROW()-5) -> 9 | H16: X | P16: X | R16: X
A17: =IF(L$6="","",L$6) -> MI | B17: =INDEX($1:$1048576,7,ROW()-5) -> 10
A18: =IF(M$6="","",M$6) -> MI | B18: =INDEX($1:$1048576,7,ROW()-5) -> 11
A19: =IF(N$6="","",N$6) -> MI | B19: =INDEX($1:$1048576,7,ROW()-5) -> 12 | D19: X | I19: X | P19: X | Q19: X
A20: =IF(O$6="","",O$6) -> P4 | B20: =INDEX($1:$1048576,7,ROW()-5) -> 13 | C20: X | D20: X
A21: =IF(P$6="","",P$6) -> P3 | B21: =INDEX($1:$1048576,7,ROW()-5) -> 14 | C21: X | D21: X | E21: X | I21: X | K21: X | N21: X
A22: =IF(Q$6="","",Q$6) -> P2 | B22: =INDEX($1:$1048576,7,ROW()-5) -> 15 | E22: X | G22: X | H22: X | N22: X
A23: =IF(R$6="","",R$6) -> P1 | B23: =INDEX($1:$1048576,7,ROW()-5) -> 16 | G23: X | H23: X | I23: X | K23: X
A24: =IF(S$6="","",S$6) | B24: =INDEX($1:$1048576,7,ROW()-5) -> 17
A25: =IF(T$6="","",T$6) | B25: =INDEX($1:$1048576,7,ROW()-5) -> 18
A26: =IF(U$6="","",U$6) | B26: =INDEX($1:$1048576,7,ROW()-5) -> 19
A27: =IF(V$6="","",V$6) | B27: =INDEX($1:$1048576,7,ROW()-5) -> 20
A28: =IF(W$6="","",W$6) | B28: =INDEX($1:$1048576,7,ROW()-5) -> 21
A29: =IF(X$6="","",X$6) | B29: =INDEX($1:$1048576,7,ROW()-5) -> 22
A30: =IF(Y$6="","",Y$6) | B30: =INDEX($1:$1048576,7,ROW()-5) -> 23
A31: =IF(Z$6="","",Z$6) | B31: =INDEX($1:$1048576,7,ROW()-5) -> 24 | AC31: X

Sheet 11 - All Red
A1: Intersection: | D1: ='1 - Cover'!C4 -> Naylor / Galloway | M1: Site ID: | N1: ='1 - Cover'!H4 -> 36
A2: Date: | B2: ='1 - Cover'!B5 -> 43546 | G2: Version: | I2: ='1 - Cover'!E5 -> 3d | M2: By: | N2: ='1 - Cover'!H5 -> R Thomson
A4: CALCULATION OF ALL- RED PERIODS FOR TRAFFIC SIGNALS
F6: PEDESTRIAN TIMINGS | S6: Calculated results cell
E7: Ped No | F7: Crossing Distance | G7: Main Grn Phase | H7: Other Phases | I7: Speed (m/s) | J7: Walk Time | K7: Clearance 1 Time | L7: Clearance 2 Time | S7: Fill in these cells where appropriate
E8: =IF('7 - Peds'!B10="","",VALUE(RIGHT('7 - Peds'!B10,1))) -> 1 | F8: 16 | G8: C | H8: B | I8: 1.2 | J8: =IF(ISNUMBER(E8),6,"") -> 6 | K8: =IF(ISNUMBER(E8),(F8/I8-L8),"") -> 9.3333333 | L8: =IF(ISNUMBER(E8),VLOOKUP(G8,A$19:O$25,15,)-2,"") -> 4
E9: =IF('7 - Peds'!B11="","",VALUE(RIGHT('7 - Peds'!B11,1))) -> 2 | F9: 20 | G9: C | I9: 1.2 | J9: =IF(ISNUMBER(E9),6,"") -> 6 | K9: =IF(ISNUMBER(E9),(F9/I9-L9),"") -> 12.666667 | L9: =IF(ISNUMBER(E9),VLOOKUP(G9,A$19:O$25,15,)-2,"") -> 4 | T9: Figure 1 | V9: Definitions
E10: =IF('7 - Peds'!B12="","",VALUE(RIGHT('7 - Peds'!B12,1))) -> 3 | F10: 15 | G10: A | I10: 1.2 | J10: =IF(ISNUMBER(E10),6,"") -> 6 | K10: =IF(ISNUMBER(E10),(F10/I10-L10),"") -> 9 | L10: =IF(ISNUMBER(E10),VLOOKUP(G10,A$19:O$25,15,)-2,"") -> 3.5 | U10: d2 | V10: Tt | W10: Tr = Tr1 - Tr2 + Tr3
E11: =IF('7 - Peds'!B13="","",VALUE(RIGHT('7 - Peds'!B13,1))) -> 4 | F11: 17 | G11: A | H11: D | I11: 1.2 | J11: =IF(ISNUMBER(E11),6,"") -> 6 | K11: =IF(ISNUMBER(E11),(F11/I11-L11),"") -> 10.666667 | L11: =IF(ISNUMBER(E11),VLOOKUP(G11,A$19:O$25,15,)-2,"") -> 3.5 | U11: 2 | V11: 0.7 | W11: ' = (d1 + L)/VL - (Ts + Tt) + 0.5
E12: =IF('7 - Peds'!B14="","",VALUE(RIGHT('7 - Peds'!B14,1))) | J12: =IF(ISNUMBER(E12),6,"") | K12: =IF(ISNUMBER(E12),(F12/I12-L12),"") | L12: =IF(ISNUMBER(E12),VLOOKUP(G12,A$19:O$25,15,)-2,"") | U12: 3 | V12: 0.9 | W12: Tr = All-red time (sec)
E13: =IF('7 - Peds'!B15="","",VALUE(RIGHT('7 - Peds'!B15,1))) | J13: =IF(ISNUMBER(E13),6,"") | K13: =IF(ISNUMBER(E13),(F13/I13-L13),"") | L13: =IF(ISNUMBER(E13),VLOOKUP(G13,A$19:O$25,15,)-2,"") | U13: 4 | V13: 1 | W13: d1 = Distance from stopline to the
E14: =IF('7 - Peds'!B16="","",VALUE(RIGHT('7 - Peds'!B16,1))) | J14: =IF(ISNUMBER(E14),6,"") | K14: =IF(ISNUMBER(E14),(F14/I14-L14),"") | L14: =IF(ISNUMBER(E14),VLOOKUP(G14,A$19:O$25,15,)-2,"") | U14: 5 | V14: 1.2 | W14: conflict point for the moving vehicle (m)
E15: =IF('7 - Peds'!B17="","",VALUE(RIGHT('7 - Peds'!B17,1))) | J15: =IF(ISNUMBER(E15),6,"") | K15: =IF(ISNUMBER(E15),(F15/I15-L15),"") | L15: =IF(ISNUMBER(E15),VLOOKUP(G15,A$19:O$25,15,)-2,"") | U15: 6 | V15: 1.3 | W15: d2 = the distance from the stopline to the
U16: 7 | V16: 1.4 | W16: conflict point for the stationary vheicle (m)
C17: SUMMARY OF ALL RED TIMINGS | U17: 8 | V17: 1.5 | W17: L = Vehicle length ( use 5.0m )
A18: Phase | B18: All-Red Periods: | E18: Speed | G18: Special All-Reds: | J18: When Used | N18: Yellow Time | O18: SCATS Intergreen | U18: 10 | V18: 1.6 | W18: vehicle through the intersection (m/s)
A19: =IF('4 - Phase Control'!A8="","",LEFT('4 - Phase Control'!A8,1)) -> A | B19: =IF(A19="","","RED"&A19&" =") -> REDA = | D19: 1.5 | E19: 50 | G19: =IF(A19="","","SRED"&A19&" =") -> SREDA = | N19: =IF(A19="","",CEILING(IF(E19=50,3.8,IF(E19=60,4.3,IF(E19=65,4.5,IF(E19=70,4.8,IF(E19=75,5,IF(E19=80,5.2,4)))))),0.5)) -> 4 | O19: =IF(A19="","",D19+N19) -> 5.5 | U19: 11 | V19: 1.7 | W19: Ts = Start-up reaction time for the stationary vehicle
A20: =IF('4 - Phase Control'!A9="","",LEFT('4 - Phase Control'!A9,1)) -> B | B20: =IF(A20="","","RED"&A20&" =") -> REDB = | D20: 2 | E20: 50 | G20: =IF(A20="","","SRED"&A20&" =") -> SREDB = | N20: =IF(A20="","",CEILING(IF(E20=50,3.8,IF(E20=60,4.3,IF(E20=65,4.5,IF(E20=70,4.8,IF(E20=75,5,IF(E20=80,5.2,4)))))),0.5)) -> 4 | O20: =IF(A20="","",D20+N20) -> 6 | U20: 12 | V20: 1.8 | W20: = 0.5 sec for vehicles
A21: =IF('4 - Phase Control'!A10="","",LEFT('4 - Phase Control'!A10,1)) -> C | B21: =IF(A21="","","RED"&A21&" =") -> REDC = | D21: 2 | E21: 50 | G21: =IF(A21="","","SRED"&A21&" =") -> SREDC = | N21: =IF(A21="","",CEILING(IF(E21=50,3.8,IF(E21=60,4.3,IF(E21=65,4.5,IF(E21=70,4.8,IF(E21=75,5,IF(E21=80,5.2,4)))))),0.5)) -> 4 | O21: =IF(A21="","",D21+N21) -> 6 | U21: 13 | V21: 1.9 | W21: = 0.3 sec for pedestrians
A22: =IF('4 - Phase Control'!A11="","",LEFT('4 - Phase Control'!A11,1)) -> D | B22: =IF(A22="","","RED"&A22&" =") -> REDD = | D22: 1.5 | E22: 50 | G22: =IF(A22="","","SRED"&A22&" =") -> SREDD = | N22: =IF(A22="","",CEILING(IF(E22=50,3.8,IF(E22=60,4.3,IF(E22=65,4.5,IF(E22=70,4.8,IF(E22=75,5,IF(E22=80,5.2,4)))))),0.5)) -> 4 | O22: =IF(A22="","",D22+N22) -> 5.5 | U22: 14 | V22: 2 | W22: Tt = Time for a stationary vehicle to accelerate
A23: =IF('4 - Phase Control'!A12="","",LEFT('4 - Phase Control'!A12,1)) -> E | B23: =IF(A23="","","RED"&A23&" =") -> REDE = | G23: =IF(A23="","","SRED"&A23&" =") -> SREDE = | N23: =IF(A23="","",CEILING(IF(E23=50,3.8,IF(E23=60,4.3,IF(E23=65,4.5,IF(E23=70,4.8,IF(E23=75,5,IF(E23=80,5.2,4)))))),0.5)) -> 4 | O23: =IF(A23="","",D23+N23) -> 4 | U23: 15 | V23: 2 | W23: and travel distance d2 to the conflict point (sec)
A24: =IF('4 - Phase Control'!A13="","",LEFT('4 - Phase Control'!A13,1)) -> F | B24: =IF(A24="","","RED"&A24&" =") -> REDF = | G24: =IF(A24="","","SRED"&A24&" =") -> SREDF = | N24: =IF(A24="","",CEILING(IF(E24=50,3.8,IF(E24=60,4.3,IF(E24=65,4.5,IF(E24=70,4.8,IF(E24=75,5,IF(E24=80,5.2,4)))))),0.5)) -> 4 | O24: =IF(A24="","",D24+N24) -> 4
A25: =IF('4 - Phase Control'!A14="","",LEFT('4 - Phase Control'!A14,1)) -> G | B25: =IF(A25="","","RED"&A25&" =") -> REDG = | G25: =IF(A25="","","SRED"&A25&" =") -> SREDG = | N25: =IF(A25="","",CEILING(IF(E25=50,3.8,IF(E25=60,4.3,IF(E25=65,4.5,IF(E25=70,4.8,IF(E25=75,5,IF(E25=80,5.2,4)))))),0.5)) -> 4 | O25: =IF(A25="","",D25+N25) -> 4 | U25: Kilometres/Hour | V25: 25 | W25: 30 | X25: 35 | Y25: 40 | Z25: 45 | AA25: 50 | AB25: 55 | AC25: 60
A27: All Reds | B27: Default = 1.0 | D27: use whichever is the greater, 1.0 or value from cell Tr(8) Vehicle/Vehicle conflict matrix | U27: Metres/Sec | V27: =V25/3.6 -> 6.9444444 | W27: =W25/3.6 -> 8.3333333 | X27: =X25/3.6 -> 9.7222222 | Y27: =Y25/3.6 -> 11.111111 | Z27: =Z25/3.6 -> 12.5 | AA27: =AA25/3.6 -> 13.888889 | AB27: =AB25/3.6 -> 15.277778 | AC27: =AC25/3.6 -> 16.666667
A28: Sreds | B28: Default = 0 | D28: use whichever is the greater, 0 or value from cell Tr(8) Vehicle/Pedestrian conflict matrix
A30: VEHICLE/VEHICLE CONFLICTS
A31: Conflict No. | B31: Green Phase | C31: To Phase | D31: Conflict Description | I31: (1) d1 (metres) | J31: (2) d2 (metres) | K31: (3) VL (m/s) | L31: (4) Ts (0.5 sec) | M31: (5) Tt (See Fig 1) | N31: (6) Tr1 ={(1)+5}/(3) | O31: (7) Tr2 =(4)+(5) | P31: (8) Tr =(6)-(7)+0.5 | S31: Red time check Phase:
A34: 1 | B34: A | C34: B/C | D34: SG6 VS SG1 | I34: 15.5 | J34: 10 | K34: 13.888889 | L34: =IF(K34=0,"",0.5) -> 0.5 | M34: =IF(J34=0,"",IF(ROUND(J34,0)<3,0.7,IF(ROUND(J34,0)<5,0.9,IF(ROUND(J34,0)<8,1.2,IF(ROUND(J34,0)<11,1.6,IF(ROUND(J34,0)<13,1.8,2)))))) -> 1.6 | N34: =IF(K34=0,"",(I34+5)/K34) -> 1.476 | O34: =IF(K34=0,"",L34+M34) -> 2.1 | P34: =IF(K34=0,"",N34-O34+0.5) -> -0.124 | S34: Off
A35: 2 | B35: A/D | C35: C | D35: SG5 VS SG2 | I35: 16.5 | J35: 11 | K35: 13.888889 | L35: =IF(K35=0,"",0.5) -> 0.5 | M35: =IF(J35=0,"",IF(ROUND(J35,0)<3,0.7,IF(ROUND(J35,0)<5,0.9,IF(ROUND(J35,0)<8,1.2,IF(ROUND(J35,0)<11,1.6,IF(ROUND(J35,0)<13,1.8,2)))))) -> 1.8 | N35: =IF(K35=0,"",(I35+5)/K35) -> 1.548 | O35: =IF(K35=0,"",L35+M35) -> 2.3 | P35: =IF(K35=0,"",N35-O35+0.5) -> -0.252
A36: 3 | B36: A | C36: C | D36: SG6RT VS SG2RT | I36: 15 | J36: 10 | K36: 11.111111 | L36: =IF(K36=0,"",0.5) -> 0.5 | M36: =IF(J36=0,"",IF(ROUND(J36,0)<3,0.7,IF(ROUND(J36,0)<5,0.9,IF(ROUND(J36,0)<8,1.2,IF(ROUND(J36,0)<11,1.6,IF(ROUND(J36,0)<13,1.8,2)))))) -> 1.6 | N36: =IF(K36=0,"",(I36+5)/K36) -> 1.8 | O36: =IF(K36=0,"",L36+M36) -> 2.1 | P36: =IF(K36=0,"",N36-O36+0.5) -> 0.2
A37: 4 | B37: B | C37: C | D37: SG3 VS SG2 | I37: 14 | J37: 17.5 | K37: 11.111111 | L37: =IF(K37=0,"",0.5) -> 0.5 | M37: =IF(J37=0,"",IF(ROUND(J37,0)<3,0.7,IF(ROUND(J37,0)<5,0.9,IF(ROUND(J37,0)<8,1.2,IF(ROUND(J37,0)<11,1.6,IF(ROUND(J37,0)<13,1.8,2)))))) -> 2 | N37: =IF(K37=0,"",(I37+5)/K37) -> 1.71 | O37: =IF(K37=0,"",L37+M37) -> 2.5 | P37: =IF(K37=0,"",N37-O37+0.5) -> -0.29
A38: 5 | B38: B/C | C38: A | D38: SG3 VS SG6RT | I38: 16 | J38: 6.5 | K38: 11.111111 | L38: =IF(K38=0,"",0.5) -> 0.5 | M38: =IF(J38=0,"",IF(ROUND(J38,0)<3,0.7,IF(ROUND(J38,0)<5,0.9,IF(ROUND(J38,0)<8,1.2,IF(ROUND(J38,0)<11,1.6,IF(ROUND(J38,0)<13,1.8,2)))))) -> 1.2 | N38: =IF(K38=0,"",(I38+5)/K38) -> 1.89 | O38: =IF(K38=0,"",L38+M38) -> 1.7 | P38: =IF(K38=0,"",N38-O38+0.5) -> 0.69
A39: 6 | B39: B/C | C39: A/D | D39: SG1 VS SG5 | I39: 19 | J39: 8.5 | K39: 13.888889 | L39: =IF(K39=0,"",0.5) -> 0.5 | M39: =IF(J39=0,"",IF(ROUND(J39,0)<3,0.7,IF(ROUND(J39,0)<5,0.9,IF(ROUND(J39,0)<8,1.2,IF(ROUND(J39,0)<11,1.6,IF(ROUND(J39,0)<13,1.8,2)))))) -> 1.6 | N39: =IF(K39=0,"",(I39+5)/K39) -> 1.728 | O39: =IF(K39=0,"",L39+M39) -> 2.1 | P39: =IF(K39=0,"",N39-O39+0.5) -> 0.128
A40: 7 | B40: C | C40: A | D40: SG2 VS SG6 | I40: 20.5 | J40: 7.5 | K40: 13.888889 | L40: =IF(K40=0,"",0.5) -> 0.5 | M40: =IF(J40=0,"",IF(ROUND(J40,0)<3,0.7,IF(ROUND(J40,0)<5,0.9,IF(ROUND(J40,0)<8,1.2,IF(ROUND(J40,0)<11,1.6,IF(ROUND(J40,0)<13,1.8,2)))))) -> 1.6 | N40: =IF(K40=0,"",(I40+5)/K40) -> 1.836 | O40: =IF(K40=0,"",L40+M40) -> 2.1 | P40: =IF(K40=0,"",N40-O40+0.5) -> 0.236
A41: 8 | B41: C | C41: A/D | D41: SG2RT VS SG7 | I41: 19.5 | J41: 5.5 | K41: 11.111111 | L41: =IF(K41=0,"",0.5) -> 0.5 | M41: =IF(J41=0,"",IF(ROUND(J41,0)<3,0.7,IF(ROUND(J41,0)<5,0.9,IF(ROUND(J41,0)<8,1.2,IF(ROUND(J41,0)<11,1.6,IF(ROUND(J41,0)<13,1.8,2)))))) -> 1.2 | N41: =IF(K41=0,"",(I41+5)/K41) -> 2.205 | O41: =IF(K41=0,"",L41+M41) -> 1.7 | P41: =IF(K41=0,"",N41-O41+0.5) -> 1.005
A42: 9 | B42: D | C42: A | D42: SG7 VS SG6 | I42: 11.5 | J42: 13.5 | K42: 11.111111 | L42: =IF(K42=0,"",0.5) -> 0.5 | M42: =IF(J42=0,"",IF(ROUND(J42,0)<3,0.7,IF(ROUND(J42,0)<5,0.9,IF(ROUND(J42,0)<8,1.2,IF(ROUND(J42,0)<11,1.6,IF(ROUND(J42,0)<13,1.8,2)))))) -> 2 | N42: =IF(K42=0,"",(I42+5)/K42) -> 1.485 | O42: =IF(K42=0,"",L42+M42) -> 2.5 | P42: =IF(K42=0,"",N42-O42+0.5) -> -0.515
A43: 10 | L43: =IF(K43=0,"",0.5) | M43: =IF(J43=0,"",IF(ROUND(J43,0)<3,0.7,IF(ROUND(J43,0)<5,0.9,IF(ROUND(J43,0)<8,1.2,IF(ROUND(J43,0)<11,1.6,IF(ROUND(J43,0)<13,1.8,2)))))) | N43: =IF(K43=0,"",(I43+5)/K43) | O43: =IF(K43=0,"",L43+M43) | P43: =IF(K43=0,"",N43-O43+0.5)
A44: 11 | L44: =IF(K44=0,"",0.5) | M44: =IF(J44=0,"",IF(ROUND(J44,0)<3,0.7,IF(ROUND(J44,0)<5,0.9,IF(ROUND(J44,0)<8,1.2,IF(ROUND(J44,0)<11,1.6,IF(ROUND(J44,0)<13,1.8,2)))))) | N44: =IF(K44=0,"",(I44+5)/K44) | O44: =IF(K44=0,"",L44+M44) | P44: =IF(K44=0,"",N44-O44+0.5)
A45: 12 | L45: =IF(K45=0,"",0.5) | M45: =IF(J45=0,"",IF(ROUND(J45,0)<3,0.7,IF(ROUND(J45,0)<5,0.9,IF(ROUND(J45,0)<8,1.2,IF(ROUND(J45,0)<11,1.6,IF(ROUND(J45,0)<13,1.8,2)))))) | N45: =IF(K45=0,"",(I45+5)/K45) | O45: =IF(K45=0,"",L45+M45) | P45: =IF(K45=0,"",N45-O45+0.5)
A47: VEHICLE/PEDESTRIAN CONFLICTS
...

Sheet Lists
A1: Controller | B1: Detectors | D1: SG | E1: calcs | F1: phases | H1: ped groups | I1: PG | J1: calcs | K1: phases | L1: SG
A2: Aldridge | B2: 32 | D2: =IF(ISNUMBER('3 - Signal Group Info'!A7),'3 - Signal Group Info'!A7,"") -> 1 | E2: =IF(ISNUMBER(D2),IF('3 - Signal Group Info'!B7="","",'3 - Signal Group Info'!B7&"/")&IF('3 - Signal Group Info'!C7="","",'3 - Signal Group Info'!C7&"/")&IF('3 - Signal Group Info'!D7="","",'3 - Signal Group Info'!D7&"/")&IF('3 - Signal Group Info'!E7="","",'3 - Signal Group Info'!E7&"/")&IF('3 - Signal Group Info'!F7="","",'3 - Signal Group Info'!F7&"/")&IF('3 - Signal Group Info'!G7="","",'3 - Signal Group Info'!G7&"/")&IF('3 - Signal Group Info'!H7="","",'3 - Signal Group Info'!H7&"/"),"") -> B/C/ | F2: =IF(LEN(E2)>0,LEFT((E2),LEN(E2)-1),"") -> B/C | H2: =IF(ISNUMBER(SEARCH("p",'3 - Signal Group Info'!A7)),'3 - Signal Group Info'!A7,"") | I2: =LEFT(H2,2) | J2: =IF(LEN(H2)>0,IF('3 - Signal Group Info'!B7="","",IF('3 - Signal Group Info'!B7="w",LEFT('3 - Signal Group Info'!B$6,1)&"/",'3 - Signal Group Info'!B7&"/"))&IF('3 - Signal Group Info'!C7="","",IF('3 - Signal Group Info'!C7="w",LEFT('3 - Signal Group Info'!C$6,1)&"/",'3 - Signal Group Info'!C7&"/"))&IF('3 - Signal Group Info'!D7="","",IF('3 - Signal Group Info'!D7="w",LEFT('3 - Signal Group Info'!D$6,1)&"/",'3 - Signal Group Info'!D7&"/"))&IF('3 - Signal Group Info'!E7="","",IF('3 - Signal Group Info'!E7="w",LEFT('3 - Signal Group Info'!E$6,1)&"/",'3 - Signal Group Info'!E7&"/"))&IF('3 - Signal Group Info'!F7="","",IF('3 - Signal Group Info'!F7="w",LEFT('3 - Signal Group Info'!F$6,1)&"/",'3 - Signal Group Info'!F7&"/"))&IF('3 - Signal Group Info'!G7="","",IF('3 - Signal Group Info'!G7="w",LEFT('3 - Signal Group Info'!G$6,1)&"/",'3 - Signal Group Info'!G7&"/"))&IF('3 - Signal Group Info'!H7="","",IF('3 - Signal Group Info'!H7="w",LEFT('3 - Signal Group Info'!H$6,1)&"/",'3 - Signal Group Info'!H7&"/")),"") | K2: =IF(LEN(J2)>0,LEFT((J2),LEN(J2)-1),"") | L2: =IF(H2="","",LEFT(RIGHT(H2,LEN(H2)-FIND("(",H2)),LEN(RIGHT(H2,LEN(H2)-FIND("(",H2)))-1))
A3: Eclipse | B3: 24 | D3: =IF(ISNUMBER('3 - Signal Group Info'!A9),'3 - Signal Group Info'!A9,"") -> 2 | E3: =IF(ISNUMBER(D3),IF('3 - Signal Group Info'!B9="","",'3 - Signal Group Info'!B9&"/")&IF('3 - Signal Group Info'!C9="","",'3 - Signal Group Info'!C9&"/")&IF('3 - Signal Group Info'!D9="","",'3 - Signal Group Info'!D9&"/")&IF('3 - Signal Group Info'!E9="","",'3 - Signal Group Info'!E9&"/")&IF('3 - Signal Group Info'!F9="","",'3 - Signal Group Info'!F9&"/")&IF('3 - Signal Group Info'!G9="","",'3 - Signal Group Info'!G9&"/")&IF('3 - Signal Group Info'!H9="","",'3 - Signal Group Info'!H9&"/"),"") -> C/ | F3: =IF(LEN(E3)>0,LEFT((E3),LEN(E3)-1),"") -> C | H3: =IF(ISNUMBER(SEARCH("p",'3 - Signal Group Info'!A9)),'3 - Signal Group Info'!A9,"") | I3: =LEFT(H3,2) | J3: =IF(LEN(H3)>0,IF('3 - Signal Group Info'!B9="","",IF('3 - Signal Group Info'!B9="w",LEFT('3 - Signal Group Info'!B$6,1)&"/",'3 - Signal Group Info'!B9&"/"))&IF('3 - Signal Group Info'!C9="","",IF('3 - Signal Group Info'!C9="w",LEFT('3 - Signal Group Info'!C$6,1)&"/",'3 - Signal Group Info'!C9&"/"))&IF('3 - Signal Group Info'!D9="","",IF('3 - Signal Group Info'!D9="w",LEFT('3 - Signal Group Info'!D$6,1)&"/",'3 - Signal Group Info'!D9&"/"))&IF('3 - Signal Group Info'!E9="","",IF('3 - Signal Group Info'!E9="w",LEFT('3 - Signal Group Info'!E$6,1)&"/",'3 - Signal Group Info'!E9&"/"))&IF('3 - Signal Group Info'!F9="","",IF('3 - Signal Group Info'!F9="w",LEFT('3 - Signal Group Info'!F$6,1)&"/",'3 - Signal Group Info'!F9&"/"))&IF('3 - Signal Group Info'!G9="","",IF('3 - Signal Group Info'!G9="w",LEFT('3 - Signal Group Info'!G$6,1)&"/",'3 - Signal Group Info'!G9&"/"))&IF('3 - Signal Group Info'!H9="","",IF('3 - Signal Group Info'!H9="w",LEFT('3 - Signal Group Info'!H$6,1)&"/",'3 - Signal Group Info'!H9&"/")),"") | K3: =IF(LEN(J3)>0,LEFT((J3),LEN(J3)-1),"") | L3: =IF(H3="","",LEFT(RIGHT(H3,LEN(H3)-FIND("(",H3)),LEN(RIGHT(H3,LEN(H3)-FIND("(",H3)))-1))
A4: PSC | B4: 16/32 | D4: =IF(ISNUMBER('3 - Signal Group Info'!A11),'3 - Signal Group Info'!A11,"") -> 3 | E4: =IF(ISNUMBER(D4),IF('3 - Signal Group Info'!B11="","",'3 - Signal Group Info'!B11&"/")&IF('3 - Signal Group Info'!C11="","",'3 - Signal Group Info'!C11&"/")&IF('3 - Signal Group Info'!D11="","",'3 - Signal Group Info'!D11&"/")&IF('3 - Signal Group Info'!E11="","",'3 - Signal Group Info'!E11&"/")&IF('3 - Signal Group Info'!F11="","",'3 - Signal Group Info'!F11&"/")&IF('3 - Signal Group Info'!G11="","",'3 - Signal Group Info'!G11&"/")&IF('3 - Signal Group Info'!H11="","",'3 - Signal Group Info'!H11&"/"),"") -> B/ | F4: =IF(LEN(E4)>0,LEFT((E4),LEN(E4)-1),"") -> B | H4: =IF(ISNUMBER(SEARCH("p",'3 - Signal Group Info'!A11)),'3 - Signal Group Info'!A11,"") | I4: =LEFT(H4,2) | J4: =IF(LEN(H4)>0,IF('3 - Signal Group Info'!B11="","",IF('3 - Signal Group Info'!B11="w",LEFT('3 - Signal Group Info'!B$6,1)&"/",'3 - Signal Group Info'!B11&"/"))&IF('3 - Signal Group Info'!C11="","",IF('3 - Signal Group Info'!C11="w",LEFT('3 - Signal Group Info'!C$6,1)&"/",'3 - Signal Group Info'!C11&"/"))&IF('3 - Signal Group Info'!D11="","",IF('3 - Signal Group Info'!D11="w",LEFT('3 - Signal Group Info'!D$6,1)&"/",'3 - Signal Group Info'!D11&"/"))&IF('3 - Signal Group Info'!E11="","",IF('3 - Signal Group Info'!E11="w",LEFT('3 - Signal Group Info'!E$6,1)&"/",'3 - Signal Group Info'!E11&"/"))&IF('3 - Signal Group Info'!F11="","",IF('3 - Signal Group Info'!F11="w",LEFT('3 - Signal Group Info'!F$6,1)&"/",'3 - Signal Group Info'!F11&"/"))&IF('3 - Signal Group Info'!G11="","",IF('3 - Signal Group Info'!G11="w",LEFT('3 - Signal Group Info'!G$6,1)&"/",'3 - Signal Group Info'!G11&"/"))&IF('3 - Signal Group Info'!H11="","",IF('3 - Signal Group Info'!H11="w",LEFT('3 - Signal Group Info'!H$6,1)&"/",'3 - Signal Group Info'!H11&"/")),"") | K4: =IF(LEN(J4)>0,LEFT((J4),LEN(J4)-1),"") | L4: =IF(H4="","",LEFT(RIGHT(H4,LEN(H4)-FIND("(",H4)),LEN(RIGHT(H4,LEN(H4)-FIND("(",H4)))-1))
A5: QTC | B5: 32 | D5: =IF(ISNUMBER('3 - Signal Group Info'!A13),'3 - Signal Group Info'!A13,"") -> 4 | E5: =IF(ISNUMBER(D5),IF('3 - Signal Group Info'!B13="","",'3 - Signal Group Info'!B13&"/")&IF('3 - Signal Group Info'!C13="","",'3 - Signal Group Info'!C13&"/")&IF('3 - Signal Group Info'!D13="","",'3 - Signal Group Info'!D13&"/")&IF('3 - Signal Group Info'!E13="","",'3 - Signal Group Info'!E13&"/")&IF('3 - Signal Group Info'!F13="","",'3 - Signal Group Info'!F13&"/")&IF('3 - Signal Group Info'!G13="","",'3 - Signal Group Info'!G13&"/")&IF('3 - Signal Group Info'!H13="","",'3 - Signal Group Info'!H13&"/"),"") -> C/ | F5: =IF(LEN(E5)>0,LEFT((E5),LEN(E5)-1),"") -> C | H5: =IF(ISNUMBER(SEARCH("p",'3 - Signal Group Info'!A13)),'3 - Signal Group Info'!A13,"") | I5: =LEFT(H5,2) | J5: =IF(LEN(H5)>0,IF('3 - Signal Group Info'!B13="","",IF('3 - Signal Group Info'!B13="w",LEFT('3 - Signal Group Info'!B$6,1)&"/",'3 - Signal Group Info'!B13&"/"))&IF('3 - Signal Group Info'!C13="","",IF('3 - Signal Group Info'!C13="w",LEFT('3 - Signal Group Info'!C$6,1)&"/",'3 - Signal Group Info'!C13&"/"))&IF('3 - Signal Group Info'!D13="","",IF('3 - Signal Group Info'!D13="w",LEFT('3 - Signal Group Info'!D$6,1)&"/",'3 - Signal Group Info'!D13&"/"))&IF('3 - Signal Group Info'!E13="","",IF('3 - Signal Group Info'!E13="w",LEFT('3 - Signal Group Info'!E$6,1)&"/",'3 - Signal Group Info'!E13&"/"))&IF('3 - Signal Group Info'!F13="","",IF('3 - Signal Group Info'!F13="w",LEFT('3 - Signal Group Info'!F$6,1)&"/",'3 - Signal Group Info'!F13&"/"))&IF('3 - Signal Group Info'!G13="","",IF('3 - Signal Group Info'!G13="w",LEFT('3 - Signal Group Info'!G$6,1)&"/",'3 - Signal Group Info'!G13&"/"))&IF('3 - Signal Group Info'!H13="","",IF('3 - Signal Group Info'!H13="w",LEFT('3 - Signal Group Info'!H$6,1)&"/",'3 - Signal Group Info'!H13&"/")),"") | K5: =IF(LEN(J5)>0,LEFT((J5),LEN(J5)-1),"") | L5: =IF(H5="","",LEFT(RIGHT(H5,LEN(H5)-FIND("(",H5)),LEN(RIGHT(H5,LEN(H5)-FIND("(",H5)))-1))
